Workbook

Sheet MARKOV
N1: Treatment A | AG1: Treatment B
B2: Indication | F2: Transition Matrix / Transition Probabilities | L2: Cycle | N2: State Membership | S2: Costs | AA2: QALYs | AE2: Cycle | AG2: State Membership | AL2: Costs | AT2: QALYs
F3: Treatment A | N3: PFS | O3: PD | P3: Dead | Q3: CHECK | S3: PFS | T3: PD | U3: Total HS | W3: Drug Cost | Y3: Total Cost A | AA3: PFS | AB3: PD | AC3: Total | AG3: PFS | AH3: PD | AI3: Dead | AJ3: CHECK | AL3: PFS | AM3: PD | AN3: Total HS | AP3: Drug Cost | AR3: Total Cost A | AT3: PFS | AU3: PD | AV3: Total
B4: Oncology | G4: PFS | H4: PD | I4: Dead | L4: 1 | N4: 1000 | O4: 0 | P4: 0 | Q4: =ROUND(SUM(N4:P4),5) -> 1000 | S4: =N4*$G$25 -> 100000 | T4: =O4*$G$26 -> 0 | U4: =SUM(S4:T4) -> 100000 | W4: =($N$4-P4)*$H$33 -> 250000 | Y4: =U4+W4 -> 350000 | AA4: =N4*$H$25 -> 850 | AB4: =O4*$H$26 -> 0 | AC4: =SUM(AA4:AB4) -> 850 | AE4: 1 | AG4: 1000 | AH4: 0 | AI4: 0 | AL4: =AG4*$G$25 -> 100000 | AM4: =AH4*$G$26 -> 0 | AN4: =SUM(AL4:AM4) -> 100000 | AP4: =($AG$4-AI4)*$H$35 -> 3268040.4 | AR4: =AN4+AP4 -> 3368040.4 | AT4: =AG4*$H$25 -> 850 | AU4: =AH4*$H$26 -> 0 | AV4: =SUM(AT4:AU4) -> 850
F5: PFS | G5: 0.94 | H5: 0.05 | I5: 0.01 | L5: 2 | N5: {=MMULT(N4:P4,$G$5:$I$7)} -> 940 | O5: 50 | P5: 10 | Q5: =ROUND(SUM(N5:P5),5) -> 1000 | S5: =N5*$G$25 -> 94000 | T5: =O5*$G$26 -> 100000 | U5: =SUM(S5:T5) -> 194000 | W5: =($N$4-P5)*$H$33 -> 247500 | Y5: =U5+W5 -> 441500 | AA5: =N5*$H$25 -> 799 | AB5: =O5*$H$26 -> 27.5 | AC5: =SUM(AA5:AB5) -> 826.5 | AE5: 2 | AG5: {=MMULT(AG4:AI4,$G$18:$I$20)} -> 952.5 | AH5: 40 | AI5: 7.5 | AL5: =AG5*$G$25 -> 95250 | AM5: =AH5*$G$26 -> 80000 | AN5: =SUM(AL5:AM5) -> 175250 | AP5: =($AG$4-AI5)*$H$35 -> 3243530.1 | AR5: =AN5+AP5 -> 3418780.1 | AT5: =AG5*$H$25 -> 809.625 | AU5: =AH5*$H$26 -> 22 | AV5: =SUM(AT5:AU5) -> 831.625
B6: Treatment Options | F6: PD | G6: 0 | H6: 0.9 | I6: 0.1 | L6: 3 | N6: {=MMULT(N5:P5,$G$5:$I$7)} -> 883.6 | O6: 92 | P6: 24.4 | Q6: =ROUND(SUM(N6:P6),5) -> 1000 | S6: =N6*$G$25 -> 88360 | T6: =O6*$G$26 -> 184000 | U6: =SUM(S6:T6) -> 272360 | W6: =($N$4-P6)*$H$33 -> 243900 | Y6: =U6+W6 -> 516260 | AA6: =N6*$H$25 -> 751.06 | AB6: =O6*$H$26 -> 50.6 | AC6: =SUM(AA6:AB6) -> 801.66 | AE6: 3 | AG6: {=MMULT(AG5:AI5,$G$18:$I$20)} -> 907.25625 | AH6: 75.1 | AI6: 17.64375 | AL6: =AG6*$G$25 -> 90725.625 | AM6: =AH6*$G$26 -> 150200 | AN6: =SUM(AL6:AM6) -> 240925.63 | AP6: =($AG$4-AI6)*$H$35 -> 3210379.9 | AR6: =AN6+AP6 -> 3451305.6 | AT6: =AG6*$H$25 -> 771.16781 | AU6: =AH6*$H$26 -> 41.305 | AV6: =SUM(AT6:AU6) -> 812.47281
F7: Dead | G7: 0 | H7: 0 | I7: 1 | L7: 4 | N7: {=MMULT(N6:P6,$G$5:$I$7)} -> 830.584 | O7: 126.98 | P7: 42.436 | Q7: =ROUND(SUM(N7:P7),5) -> 1000 | S7: =N7*$G$25 -> 83058.4 | T7: =O7*$G$26 -> 253960 | U7: =SUM(S7:T7) -> 337018.4 | W7: =($N$4-P7)*$H$33 -> 239391 | Y7: =U7+W7 -> 576409.4 | AA7: =N7*$H$25 -> 705.9964 | AB7: =O7*$H$26 -> 69.839 | AC7: =SUM(AA7:AB7) -> 775.8354 | AE7: 4 | AG7: {=MMULT(AG6:AI6,$G$18:$I$20)} -> 864.16158 | AH7: 105.75775 | AI7: 30.080672 | AL7: =AG7*$G$25 -> 86416.158 | AM7: =AH7*$G$26 -> 211515.5 | AN7: =SUM(AL7:AM7) -> 297931.66 | AP7: =($AG$4-AI7)*$H$35 -> 3169735.6 | AR7: =AN7+AP7 -> 3467667.2 | AT7: =AG7*$H$25 -> 734.53734 | AU7: =AH7*$H$26 -> 58.166763 | AV7: =SUM(AT7:AU7) -> 792.7041
B8: Treatment A | L8: 5 | N8: {=MMULT(N7:P7,$G$5:$I$7)} -> 780.74896 | O8: 155.8112 | P8: 63.43984 | Q8: =ROUND(SUM(N8:P8),5) -> 1000 | S8: =N8*$G$25 -> 78074.896 | T8: =O8*$G$26 -> 311622.4 | U8: =SUM(S8:T8) -> 389697.3 | W8: =($N$4-P8)*$H$33 -> 234140.04 | Y8: =U8+W8 -> 623837.34 | AA8: =N8*$H$25 -> 663.63662 | AB8: =O8*$H$26 -> 85.69616 | AC8: =SUM(AA8:AB8) -> 749.33278 | AE8: 5 | AG8: {=MMULT(AG7:AI7,$G$18:$I$20)} -> 823.1139 | AH8: 132.39238 | AI8: 44.493715 | AL8: =AG8*$G$25 -> 82311.39 | AM8: =AH8*$G$26 -> 264784.76 | AN8: =SUM(AL8:AM8) -> 347096.15 | AP8: =($AG$4-AI8)*$H$35 -> 3122633.2 | AR8: =AN8+AP8 -> 3469729.3 | AT8: =AG8*$H$25 -> 699.64682 | AU8: =AH8*$H$26 -> 72.81581 | AV8: =SUM(AT8:AU8) -> 772.46263
F9: Adjust Transition Probailities for Treatment B | L9: 6 | N9: {=MMULT(N8:P8,$G$5:$I$7)} -> 733.90402 | O9: 179.26753 | P9: 86.82845 | Q9: =ROUND(SUM(N9:P9),5) -> 1000 | S9: =N9*$G$25 -> 73390.402 | T9: =O9*$G$26 -> 358535.06 | U9: =SUM(S9:T9) -> 431925.46 | W9: =($N$4-P9)*$H$33 -> 228292.89 | Y9: =U9+W9 -> 660218.35 | AA9: =N9*$H$25 -> 623.81842 | AB9: =O9*$H$26 -> 98.59714 | AC9: =SUM(AA9:AB9) -> 722.41556 | AE9: 6 | AG9: {=MMULT(AG8:AI8,$G$18:$I$20)} -> 784.01599 | AH9: 155.38751 | AI9: 60.596498 | AL9: =AG9*$G$25 -> 78401.599 | AM9: =AH9*$G$26 -> 310775.02 | AN9: =SUM(AL9:AM9) -> 389176.62 | AP9: =($AG$4-AI9)*$H$35 -> 3070008.6 | AR9: =AN9+AP9 -> 3459185.2 | AT9: =AG9*$H$25 -> 666.41359 | AU9: =AH9*$H$26 -> 85.46313 | AV9: =SUM(AT9:AU9) -> 751.87672
B10: Treatment B | H10: Probability B | J10: Probability A | L10: 7 | N10: {=MMULT(N9:P9,$G$5:$I$7)} -> 689.86978 | O10: 198.03598 | P10: 112.09424 | Q10: =ROUND(SUM(N10:P10),5) -> 1000 | S10: =N10*$G$25 -> 68986.978 | T10: =O10*$G$26 -> 396071.95 | U10: =SUM(S10:T10) -> 465058.93 | W10: =($N$4-P10)*$H$33 -> 221976.44 | Y10: =U10+W10 -> 687035.37 | AA10: =N10*$H$25 -> 586.38931 | AB10: =O10*$H$26 -> 108.91979 | AC10: =SUM(AA10:AB10) -> 695.3091 | AE10: 7 | AG10: {=MMULT(AG9:AI9,$G$18:$I$20)} -> 746.77523 | AH10: 175.09409 | AI10: 78.130681 | AL10: =AG10*$G$25 -> 74677.523 | AM10: =AH10*$G$26 -> 350188.17 | AN10: =SUM(AL10:AM10) -> 424865.7 | AP10: =($AG$4-AI10)*$H$35 -> 3012706.2 | AR10: =AN10+AP10 -> 3437571.9 | AT10: =AG10*$H$25 -> 634.75895 | AU10: =AH10*$H$26 -> 96.301747 | AV10: =SUM(AT10:AU10) -> 731.0607
F11: From | G11: To | H11: SIMPLE | I11: "By-the-Book" | J11: (for comparison) | L11: 8 | N11: {=MMULT(N10:P10,$G$5:$I$7)} -> 648.47759 | O11: 212.72587 | P11: 138.79654 | Q11: =ROUND(SUM(N11:P11),5) -> 1000 | S11: =N11*$G$25 -> 64847.759 | T11: =O11*$G$26 -> 425451.74 | U11: =SUM(S11:T11) -> 490299.49 | W11: =($N$4-P11)*$H$33 -> 215300.87 | Y11: =U11+W11 -> 705600.36 | AA11: =N11*$H$25 -> 551.20596 | AB11: =O11*$H$26 -> 116.99923 | AC11: =SUM(AA11:AB11) -> 668.20518 | AE11: 8 | AG11: {=MMULT(AG10:AI10,$G$18:$I$20)} -> 711.30341 | AH11: 191.83304 | AI11: 96.863552 | AL11: =AG11*$G$25 -> 71130.341 | AM11: =AH11*$G$26 -> 383666.08 | AN11: =SUM(AL11:AM11) -> 454796.42 | AP11: =($AG$4-AI11)*$H$35 -> 2951486.4 | AR11: =AN11+AP11 -> 3406282.9 | AT11: =AG11*$H$25 -> 604.6079 | AU11: =AH11*$H$26 -> 105.50817 | AV11: =SUM(AT11:AU11) -> 710.11607
B12: Treatment Efficacy | F12: PFS | G12: PD | H12: =H5*D20 -> 0.04 | I12: 0.0402 | J12: =H5 -> 0.05 | L12: 9 | N12: {=MMULT(N11:P11,$G$5:$I$7)} -> 609.56894 | O12: 223.87716 | P12: 166.5539 | Q12: =ROUND(SUM(N12:P12),5) -> 1000 | S12: =N12*$G$25 -> 60956.894 | T12: =O12*$G$26 -> 447754.32 | U12: =SUM(S12:T12) -> 508711.22 | W12: =($N$4-P12)*$H$33 -> 208361.52 | Y12: =U12+W12 -> 717072.74 | AA12: =N12*$H$25 -> 518.1336 | AB12: =O12*$H$26 -> 123.13244 | AC12: =SUM(AA12:AB12) -> 641.26604 | AE12: 9 | AG12: {=MMULT(AG11:AI11,$G$18:$I$20)} -> 677.5165 | AH12: 205.8977 | AI12: 116.58581 | AL12: =AG12*$G$25 -> 67751.65 | AM12: =AH12*$G$26 -> 411795.39 | AN12: =SUM(AL12:AM12) -> 479547.04 | AP12: =($AG$4-AI12)*$H$35 -> 2887033.3 | AR12: =AN12+AP12 -> 3366580.4 | AT12: =AG12*$H$25 -> 575.88902 | AU12: =AH12*$H$26 -> 113.24373 | AV12: =SUM(AT12:AU12) -> 689.13276
F13: PFS | G13: Dead | H13: =I5*D17 -> 0.0075 | I13: 0.0075 | J13: =I5 -> 0.01 | L13: 10 | N13: {=MMULT(N12:P12,$G$5:$I$7)} -> 572.9948 | O13: 231.96789 | P13: 195.03731 | Q13: =ROUND(SUM(N13:P13),5) -> 1000 | S13: =N13*$G$25 -> 57299.48 | T13: =O13*$G$26 -> 463935.78 | U13: =SUM(S13:T13) -> 521235.26 | W13: =($N$4-P13)*$H$33 -> 201240.67 | Y13: =U13+W13 -> 722475.94 | AA13: =N13*$H$25 -> 487.04558 | AB13: =O13*$H$26 -> 127.58234 | AC13: =SUM(AA13:AB13) -> 614.62792 | AE13: 10 | AG13: {=MMULT(AG12:AI12,$G$18:$I$20)} -> 645.33446 | AH13: 217.55603 | AI13: 137.10951 | AL13: =AG13*$G$25 -> 64533.446 | AM13: =AH13*$G$26 -> 435112.06 | AN13: =SUM(AL13:AM13) -> 499645.51 | AP13: =($AG$4-AI13)*$H$35 -> 2819961 | AR13: =AN13+AP13 -> 3319606.5 | AT13: =AG13*$H$25 -> 548.53429 | AU13: =AH13*$H$26 -> 119.65582 | AV13: =SUM(AT13:AU13) -> 668.19011
B14: We know that… | F14: PD | G14: Dead | H14: =I6*D17 -> 0.075 | I14: 0.0759 | J14: =I6 -> 0.1 | L14: 11 | N14: {=MMULT(N13:P13,$G$5:$I$7)} -> 538.61511 | O14: 237.42084 | P14: 223.96404 | Q14: =ROUND(SUM(N14:P14),5) -> 1000 | S14: =N14*$G$25 -> 53861.511 | T14: =O14*$G$26 -> 474841.68 | U14: =SUM(S14:T14) -> 528703.2 | W14: =($N$4-P14)*$H$33 -> 194008.99 | Y14: =U14+W14 -> 722712.19 | AA14: =N14*$H$25 -> 457.82285 | AB14: =O14*$H$26 -> 130.58146 | AC14: =SUM(AA14:AB14) -> 588.40431 | AE14: 11 | AG14: {=MMULT(AG13:AI13,$G$18:$I$20)} -> 614.68108 | AH14: 227.05271 | AI14: 158.26622 | AL14: =AG14*$G$25 -> 61468.108 | AM14: =AH14*$G$26 -> 454105.41 | AN14: =SUM(AL14:AM14) -> 515573.52 | AP14: =($AG$4-AI14)*$H$35 -> 2750820 | AR14: =AN14+AP14 -> 3266393.6 | AT14: =AG14*$H$25 -> 522.47892 | AU14: =AH14*$H$26 -> 124.87899 | AV14: =SUM(AT14:AU14) -> 647.3579
D15: HR | L15: 12 | N15: {=MMULT(N14:P14,$G$5:$I$7)} -> 506.29821 | O15: 240.60951 | P15: 253.09228 | Q15: =ROUND(SUM(N15:P15),5) -> 1000 | S15: =N15*$G$25 -> 50629.821 | T15: =O15*$G$26 -> 481219.03 | U15: =SUM(S15:T15) -> 531848.85 | W15: =($N$4-P15)*$H$33 -> 186726.93 | Y15: =U15+W15 -> 718575.78 | AA15: =N15*$H$25 -> 430.35348 | AB15: =O15*$H$26 -> 132.33523 | AC15: =SUM(AA15:AB15) -> 562.68871 | AE15: 12 | AG15: {=MMULT(AG14:AI14,$G$18:$I$20)} -> 585.48373 | AH15: 234.611 | AI15: 179.90528 | AL15: =AG15*$G$25 -> 58548.373 | AM15: =AH15*$G$26 -> 469221.99 | AN15: =SUM(AL15:AM15) -> 527770.37 | AP15: =($AG$4-AI15)*$H$35 -> 2680102.7 | AR15: =AN15+AP15 -> 3207873.1 | AT15: =AG15*$H$25 -> 497.66117 | AU15: =AH15*$H$26 -> 129.03605 | AV15: =SUM(AT15:AU15) -> 626.69721
B16: - Treatment B is associated with a lower risk of death compared to Treatment A, with a Hazard Ratio (HR) of 0.75 for OS | F16: Treatment B | L16: 13 | N16: {=MMULT(N15:P15,$G$5:$I$7)} -> 475.92031 | O16: 241.86347 | P16: 282.21621 | Q16: =ROUND(SUM(N16:P16),5) -> 1000 | S16: =N16*$G$25 -> 47592.031 | T16: =O16*$G$26 -> 483726.95 | U16: =SUM(S16:T16) -> 531318.98 | W16: =($N$4-P16)*$H$33 -> 179445.95 | Y16: =U16+W16 -> 710764.92 | AA16: =N16*$H$25 -> 404.53227 | AB16: =O16*$H$26 -> 133.02491 | AC16: =SUM(AA16:AB16) -> 537.55718 | AE16: 13 | AG16: {=MMULT(AG15:AI15,$G$18:$I$20)} -> 557.67325 | AH16: 240.43452 | AI16: 201.89223 | AL16: =AG16*$G$25 -> 55767.325 | AM16: =AH16*$G$26 -> 480869.04 | AN16: =SUM(AL16:AM16) -> 536636.37 | AP16: =($AG$4-AI16)*$H$35 -> 2608248.5 | AR16: =AN16+AP16 -> 3144884.8 | AT16: =AG16*$H$25 -> 474.02226 | AU16: =AH16*$H$26 -> 132.23899 | AV16: =SUM(AT16:AU16) -> 606.26125
D17: 0.75 | G17: PFS | H17: PD | I17: Dead | L17: 14 | N17: {=MMULT(N16:P16,$G$5:$I$7)} -> 447.3651 | O17: 241.47314 | P17: 311.16176 | Q17: =ROUND(SUM(N17:P17),5) -> 1000 | S17: =N17*$G$25 -> 44736.51 | T17: =O17*$G$26 -> 482946.28 | U17: =SUM(S17:T17) -> 527682.79 | W17: =($N$4-P17)*$H$33 -> 172209.56 | Y17: =U17+W17 -> 699892.35 | AA17: =N17*$H$25 -> 380.26033 | AB17: =O17*$H$26 -> 132.81023 | AC17: =SUM(AA17:AB17) -> 513.07056 | AE17: 14 | AG17: {=MMULT(AG16:AI16,$G$18:$I$20)} -> 531.18377 | AH17: 244.70886 | AI17: 224.10737 | AL17: =AG17*$G$25 -> 53118.377 | AM17: =AH17*$G$26 -> 489417.72 | AN17: =SUM(AL17:AM17) -> 542536.1 | AP17: =($AG$4-AI17)*$H$35 -> 2535648.5 | AR17: =AN17+AP17 -> 3078184.6 | AT17: =AG17*$H$25 -> 451.5062 | AU17: =AH17*$H$26 -> 134.58987 | AV17: =SUM(AT17:AU17) -> 586.09608
F18: PFS | G18: =1-H18-I18 -> 0.9525 | H18: =H12 -> 0.04 | I18: =H13 -> 0.0075 | L18: 15 | N18: {=MMULT(N17:P17,$G$5:$I$7)} -> 420.52319 | O18: 239.69408 | P18: 339.78273 | Q18: =ROUND(SUM(N18:P18),5) -> 1000 | S18: =N18*$G$25 -> 42052.319 | T18: =O18*$G$26 -> 479388.16 | U18: =SUM(S18:T18) -> 521440.48 | W18: =($N$4-P18)*$H$33 -> 165054.32 | Y18: =U18+W18 -> 686494.8 | AA18: =N18*$H$25 -> 357.44471 | AB18: =O18*$H$26 -> 131.83175 | AC18: =SUM(AA18:AB18) -> 489.27646 | AE18: 15 | AG18: {=MMULT(AG17:AI17,$G$18:$I$20)} -> 505.95254 | AH18: 247.60305 | AI18: 246.44441 | AL18: =AG18*$G$25 -> 50595.254 | AM18: =AH18*$G$26 -> 495206.1 | AN18: =SUM(AL18:AM18) -> 545801.35 | AP18: =($AG$4-AI18)*$H$35 -> 2462650.1 | AR18: =AN18+AP18 -> 3008451.5 | AT18: =AG18*$H$25 -> 430.05966 | AU18: =AH18*$H$26 -> 136.18168 | AV18: =SUM(AT18:AU18) -> 566.24134
B19: - Treatment B also has a lower risk of disease progression compared to Treatment A, with a HR of 0.8 for PFS | F19: PD | G19: 0 | H19: =1-I19 -> 0.925 | I19: =H14 -> 0.075 | L19: 16 | N19: {=MMULT(N18:P18,$G$5:$I$7)} -> 395.2918 | O19: 236.75083 | P19: 367.95737 | Q19: =ROUND(SUM(N19:P19),5) -> 1000 | S19: =N19*$G$25 -> 39529.18 | T19: =O19*$G$26 -> 473501.67 | U19: =SUM(S19:T19) -> 513030.85 | W19: =($N$4-P19)*$H$33 -> 158010.66 | Y19: =U19+W19 -> 671041.5 | AA19: =N19*$H$25 -> 335.99803 | AB19: =O19*$H$26 -> 130.21296 | AC19: =SUM(AA19:AB19) -> 466.21099 | AE19: 16 | AG19: {=MMULT(AG18:AI18,$G$18:$I$20)} -> 481.91979 | AH19: 249.27092 | AI19: 268.80928 | AL19: =AG19*$G$25 -> 48191.979 | AM19: =AH19*$G$26 -> 498541.84 | AN19: =SUM(AL19:AM19) -> 546733.82 | AP19: =($AG$4-AI19)*$H$35 -> 2389560.8 | AR19: =AN19+AP19 -> 2936294.6 | AT19: =AG19*$H$25 -> 409.63183 | AU19: =AH19*$H$26 -> 137.09901 | AV19: =SUM(AT19:AU19) -> 546.73083
D20: 0.8 | F20: Dead | G20: 0 | H20: 0 | I20: 1 | L20: 17 | N20: {=MMULT(N19:P19,$G$5:$I$7)} -> 371.57429 | O20: 232.84034 | P20: 395.58537 | Q20: =ROUND(SUM(N20:P20),5) -> 1000 | S20: =N20*$G$25 -> 37157.429 | T20: =O20*$G$26 -> 465680.68 | U20: =SUM(S20:T20) -> 502838.11 | W20: =($N$4-P20)*$H$33 -> 151103.66 | Y20: =U20+W20 -> 653941.77 | AA20: =N20*$H$25 -> 315.83815 | AB20: =O20*$H$26 -> 128.06219 | AC20: =SUM(AA20:AB20) -> 443.90033 | AE20: 17 | AG20: {=MMULT(AG19:AI19,$G$18:$I$20)} -> 459.0286 | AH20: 249.85239 | AI20: 291.119 | AL20: =AG20*$G$25 -> 45902.86 | AM20: =AH20*$G$26 -> 499704.79 | AN20: =SUM(AL20:AM20) -> 545607.65 | AP20: =($AG$4-AI20)*$H$35 -> 2316651.8 | AR20: =AN20+AP20 -> 2862259.4 | AT20: =AG20*$H$25 -> 390.17431 | AU20: =AH20*$H$26 -> 137.41882 | AV20: =SUM(AT20:AU20) -> 527.59313
L21: 18 | N21: {=MMULT(N20:P20,$G$5:$I$7)} -> 349.27983 | O21: 228.13502 | P21: 422.58515 | Q21: =ROUND(SUM(N21:P21),5) -> 1000 | S21: =N21*$G$25 -> 34927.983 | T21: =O21*$G$26 -> 456270.04 | U21: =SUM(S21:T21) -> 491198.02 | W21: =($N$4-P21)*$H$33 -> 144353.71 | Y21: =U21+W21 -> 635551.74 | AA21: =N21*$H$25 -> 296.88786 | AB21: =O21*$H$26 -> 125.47426 | AC21: =SUM(AA21:AB21) -> 422.36212 | AE21: 18 | AG21: {=MMULT(AG20:AI20,$G$18:$I$20)} -> 437.22475 | AH21: 249.47461 | AI21: 313.30065 | AL21: =AG21*$G$25 -> 43722.475 | AM21: =AH21*$G$26 -> 498949.22 | AN21: =SUM(AL21:AM21) -> 542671.69 | AP21: =($AG$4-AI21)*$H$35 -> 2244161.3 | AR21: =AN21+AP21 -> 2786832.9 | AT21: =AG21*$H$25 -> 371.64103 | AU21: =AH21*$H$26 -> 137.21103 | AV21: =SUM(AT21:AU21) -> 508.85207
B22: Defining Health States | F22: Health State Payoffs | L22: 19 | N22: {=MMULT(N21:P21,$G$5:$I$7)} -> 328.32304 | O22: 222.78551 | P22: 448.89145 | Q22: =ROUND(SUM(N22:P22),5) -> 1000 | S22: =N22*$G$25 -> 32832.304 | T22: =O22*$G$26 -> 445571.02 | U22: =SUM(S22:T22) -> 478403.32 | W22: =($N$4-P22)*$H$33 -> 137777.14 | Y22: =U22+W22 -> 616180.46 | AA22: =N22*$H$25 -> 279.07459 | AB22: =O22*$H$26 -> 122.53203 | AC22: =SUM(AA22:AB22) -> 401.60662 | AE22: 19 | AG22: {=MMULT(AG21:AI21,$G$18:$I$20)} -> 416.45657 | AH22: 248.253 | AI22: 335.29043 | AL22: =AG22*$G$25 -> 41645.657 | AM22: =AH22*$G$26 -> 496506 | AN22: =SUM(AL22:AM22) -> 538151.66 | AP22: =($AG$4-AI22)*$H$35 -> 2172297.8 | AR22: =AN22+AP22 -> 2710449.4 | AT22: =AG22*$H$25 -> 353.98808 | AU22: =AH22*$H$26 -> 136.53915 | AV22: =SUM(AT22:AU22) -> 490.52724
L23: 20 | N23: {=MMULT(N22:P22,$G$5:$I$7)} -> 308.62366 | O23: 216.92311 | P23: 474.45323 | Q23: =ROUND(SUM(N23:P23),5) -> 1000 | S23: =N23*$G$25 -> 30862.366 | T23: =O23*$G$26 -> 433846.22 | U23: =SUM(S23:T23) -> 464708.59 | W23: =($N$4-P23)*$H$33 -> 131386.69 | Y23: =U23+W23 -> 596095.28 | AA23: =N23*$H$25 -> 262.33011 | AB23: =O23*$H$26 -> 119.30771 | AC23: =SUM(AA23:AB23) -> 381.63782 | AE23: 20 | AG23: {=MMULT(AG22:AI22,$G$18:$I$20)} -> 396.67488 | AH23: 246.29229 | AI23: 357.03283 | AL23: =AG23*$G$25 -> 39667.488 | AM23: =AH23*$G$26 -> 492584.58 | AN23: =SUM(AL23:AM23) -> 532252.07 | AP23: =($AG$4-AI23)*$H$35 -> 2101242.7 | AR23: =AN23+AP23 -> 2633494.8 | AT23: =AG23*$H$25 -> 337.17365 | AU23: =AH23*$H$26 -> 135.46076 | AV23: =SUM(AT23:AU23) -> 472.63441
B24: Progression-Free Survival (PFS) | F24: State | G24: Costs | H24: QALYs | L24: 21 | N24: {=MMULT(N23:P23,$G$5:$I$7)} -> 290.10624 | O24: 210.66198 | P24: 499.23178 | Q24: =ROUND(SUM(N24:P24),5) -> 1000 | S24: =N24*$G$25 -> 29010.624 | T24: =O24*$G$26 -> 421323.97 | U24: =SUM(S24:T24) -> 450334.59 | W24: =($N$4-P24)*$H$33 -> 125192.06 | Y24: =U24+W24 -> 575526.65 | AA24: =N24*$H$25 -> 246.5903 | AB24: =O24*$H$26 -> 115.86409 | AC24: =SUM(AA24:AB24) -> 362.4544 | AE24: 21 | AG24: {=MMULT(AG23:AI23,$G$18:$I$20)} -> 377.83283 | AH24: 243.68736 | AI24: 378.47981 | AL24: =AG24*$G$25 -> 37783.283 | AM24: =AH24*$G$26 -> 487374.73 | AN24: =SUM(AL24:AM24) -> 525158.01 | AP24: =($AG$4-AI24)*$H$35 -> 2031153.1 | AR24: =AN24+AP24 -> 2556311.1 | AT24: =AG24*$H$25 -> 321.1579 | AU24: =AH24*$H$26 -> 134.02805 | AV24: =SUM(AT24:AU24) -> 455.18595
B25: Progressed Disease (PD) | F25: PFS | G25: 100 | H25: 0.85 | L25: 22 | N25: {=MMULT(N24:P24,$G$5:$I$7)} -> 272.69987 | O25: 204.1011 | P25: 523.19904 | Q25: =ROUND(SUM(N25:P25),5) -> 1000 | S25: =N25*$G$25 -> 27269.987 | T25: =O25*$G$26 -> 408202.19 | U25: =SUM(S25:T25) -> 435472.18 | W25: =($N$4-P25)*$H$33 -> 119200.24 | Y25: =U25+W25 -> 554672.42 | AA25: =N25*$H$25 -> 231.79489 | AB25: =O25*$H$26 -> 112.2556 | AC25: =SUM(AA25:AB25) -> 344.05049 | AE25: 22 | AG25: {=MMULT(AG24:AI24,$G$18:$I$20)} -> 359.88577 | AH25: 240.52412 | AI25: 399.59011 | AL25: =AG25*$G$25 -> 35988.577 | AM25: =AH25*$G$26 -> 481048.25 | AN25: =SUM(AL25:AM25) -> 517036.83 | AP25: =($AG$4-AI25)*$H$35 -> 1962163.8 | AR25: =AN25+AP25 -> 2479200.6 | AT25: =AG25*$H$25 -> 305.9029 | AU25: =AH25*$H$26 -> 132.28827 | AV25: =SUM(AT25:AU25) -> 438.19117
B26: Dead | F26: PD | G26: 2000 | H26: 0.55 | L26: 23 | N26: {=MMULT(N25:P25,$G$5:$I$7)} -> 256.33787 | O26: 197.32598 | P26: 546.33614 | Q26: =ROUND(SUM(N26:P26),5) -> 1000 | S26: =N26*$G$25 -> 25633.787 | T26: =O26*$G$26 -> 394651.96 | U26: =SUM(S26:T26) -> 420285.75 | W26: =($N$4-P26)*$H$33 -> 113415.96 | Y26: =U26+W26 -> 533701.71 | AA26: =N26*$H$25 -> 217.88719 | AB26: =O26*$H$26 -> 108.52929 | AC26: =SUM(AA26:AB26) -> 326.41648 | AE26: 23 | AG26: {=MMULT(AG25:AI25,$G$18:$I$20)} -> 342.79119 | AH26: 236.88025 | AI26: 420.32856 | AL26: =AG26*$G$25 -> 34279.119 | AM26: =AH26*$G$26 -> 473760.49 | AN26: =SUM(AL26:AM26) -> 508039.61 | AP26: =($AG$4-AI26)*$H$35 -> 1894389.7 | AR26: =AN26+AP26 -> 2402429.3 | AT26: =AG26*$H$25 -> 291.37251 | AU26: =AH26*$H$26 -> 130.28414 | AV26: =SUM(AT26:AU26) -> 421.65665
F27: Dead | G27: 0 | H27: 0 | L27: 24 | N27: {=MMULT(N26:P26,$G$5:$I$7)} -> 240.9576 | O27: 190.41028 | P27: 568.63212 | Q27: =ROUND(SUM(N27:P27),5) -> 1000 | S27: =N27*$G$25 -> 24095.76 | T27: =O27*$G$26 -> 380820.55 | U27: =SUM(S27:T27) -> 404916.31 | W27: =($N$4-P27)*$H$33 -> 107841.97 | Y27: =U27+W27 -> 512758.28 | AA27: =N27*$H$25 -> 204.81396 | AB27: =O27*$H$26 -> 104.72565 | AC27: =SUM(AA27:AB27) -> 309.53961 | AE27: 24 | AG27: {=MMULT(AG26:AI26,$G$18:$I$20)} -> 326.50861 | AH27: 232.82587 | AI27: 440.66551 | AL27: =AG27*$G$25 -> 32650.861 | AM27: =AH27*$G$26 -> 465651.75 | AN27: =SUM(AL27:AM27) -> 498302.61 | AP27: =($AG$4-AI27)*$H$35 -> 1827927.7 | AR27: =AN27+AP27 -> 2326230.3 | AT27: =AG27*$H$25 -> 277.53232 | AU27: =AH27*$H$26 -> 128.05423 | AV27: =SUM(AT27:AU27) -> 405.58655
B28: Model Diagram | L28: 25 | N28: {=MMULT(N27:P27,$G$5:$I$7)} -> 226.50015 | O28: 183.41713 | P28: 590.08273 | Q28: =ROUND(SUM(N28:P28),5) -> 1000 | S28: =N28*$G$25 -> 22650.015 | T28: =O28*$G$26 -> 366834.26 | U28: =SUM(S28:T28) -> 389484.27 | W28: =($N$4-P28)*$H$33 -> 102479.32 | Y28: =U28+W28 -> 491963.59 | AA28: =N28*$H$25 -> 192.52512 | AB28: =O28*$H$26 -> 100.87942 | AC28: =SUM(AA28:AB28) -> 293.40454 | AE28: 25 | AG28: {=MMULT(AG27:AI27,$G$18:$I$20)} -> 310.99945 | AH28: 228.42428 | AI28: 460.57627 | AL28: =AG28*$G$25 -> 31099.945 | AM28: =AH28*$G$26 -> 456848.56 | AN28: =SUM(AL28:AM28) -> 487948.5 | AP28: =($AG$4-AI28)*$H$35 -> 1762858.6 | AR28: =AN28+AP28 -> 2250807.1 | AT28: =AG28*$H$25 -> 264.34953 | AU28: =AH28*$H$26 -> 125.63335 | AV28: =SUM(AT28:AU28) -> 389.98289
L29: 26 | N29: {=MMULT(N28:P28,$G$5:$I$7)} -> 212.91014 | O29: 176.40042 | P29: 610.68944 | Q29: =ROUND(SUM(N29:P29),5) -> 1000 | S29: =N29*$G$25 -> 21291.014 | T29: =O29*$G$26 -> 352800.85 | U29: =SUM(S29:T29) -> 374091.86 | W29: =($N$4-P29)*$H$33 -> 97327.64 | Y29: =U29+W29 -> 471419.5 | AA29: =N29*$H$25 -> 180.97362 | AB29: =O29*$H$26 -> 97.020233 | AC29: =SUM(AA29:AB29) -> 277.99385 | AE29: 26 | AG29: {=MMULT(AG28:AI28,$G$18:$I$20)} -> 296.22698 | AH29: 223.73244 | AI29: 480.04059 | AL29: =AG29*$G$25 -> 29622.698 | AM29: =AH29*$G$26 -> 447464.87 | AN29: =SUM(AL29:AM29) -> 477087.57 | AP29: =($AG$4-AI29)*$H$35 -> 1699248.4 | AR29: =AN29+AP29 -> 2176336 | AT29: =AG29*$H$25 -> 251.79293 | AU29: =AH29*$H$26 -> 123.05284 | AV29: =SUM(AT29:AU29) -> 374.84577
F30: Treatment Acquisition Cost | L30: 27 | N30: {=MMULT(N29:P29,$G$5:$I$7)} -> 200.13553 | O30: 169.40589 | P30: 630.45858 | Q30: =ROUND(SUM(N30:P30),5) -> 1000 | S30: =N30*$G$25 -> 20013.553 | T30: =O30*$G$26 -> 338811.78 | U30: =SUM(S30:T30) -> 358825.33 | W30: =($N$4-P30)*$H$33 -> 92385.354 | Y30: =U30+W30 -> 451210.68 | AA30: =N30*$H$25 -> 170.1152 | AB30: =O30*$H$26 -> 93.173238 | AC30: =SUM(AA30:AB30) -> 263.28844 | AE30: 27 | AG30: {=MMULT(AG29:AI29,$G$18:$I$20)} -> 282.1562 | AH30: 218.80158 | AI30: 499.04222 | AL30: =AG30*$G$25 -> 28215.62 | AM30: =AH30*$G$26 -> 437603.16 | AN30: =SUM(AL30:AM30) -> 465818.78 | AP30: =($AG$4-AI30)*$H$35 -> 1637150.3 | AR30: =AN30+AP30 -> 2102969.1 | AT30: =AG30*$H$25 -> 239.83277 | AU30: =AH30*$H$26 -> 120.34087 | AV30: =SUM(AT30:AU30) -> 360.17364
L31: 28 | N31: {=MMULT(N30:P30,$G$5:$I$7)} -> 188.1274 | O31: 162.47208 | P31: 649.40053 | Q31: =ROUND(SUM(N31:P31),5) -> 1000 | S31: =N31*$G$25 -> 18812.74 | T31: =O31*$G$26 -> 324944.15 | U31: =SUM(S31:T31) -> 343756.89 | W31: =($N$4-P31)*$H$33 -> 87649.868 | Y31: =U31+W31 -> 431406.76 | AA31: =N31*$H$25 -> 159.90829 | AB31: =O31*$H$26 -> 89.359641 | AC31: =SUM(AA31:AB31) -> 249.26793 | AE31: 28 | AG31: {=MMULT(AG30:AI30,$G$18:$I$20)} -> 268.75378 | AH31: 213.67771 | AI31: 517.56851 | AL31: =AG31*$G$25 -> 26875.378 | AM31: =AH31*$G$26 -> 427355.42 | AN31: =SUM(AL31:AM31) -> 454230.8 | AP31: =($AG$4-AI31)*$H$35 -> 1576605.6 | AR31: =AN31+AP31 -> 2030836.4 | AT31: =AG31*$H$25 -> 228.44071 | AU31: =AH31*$H$26 -> 117.52274 | AV31: =SUM(AT31:AU31) -> 345.96345
H32: per cycle cost | L32: 29 | N32: {=MMULT(N31:P31,$G$5:$I$7)} -> 176.83975 | O32: 155.63124 | P32: 667.52901 | Q32: =ROUND(SUM(N32:P32),5) -> 1000 | S32: =N32*$G$25 -> 17683.975 | T32: =O32*$G$26 -> 311262.48 | U32: =SUM(S32:T32) -> 328946.45 | W32: =($N$4-P32)*$H$33 -> 83117.748 | Y32: =U32+W32 -> 412064.2 | AA32: =N32*$H$25 -> 150.31379 | AB32: =O32*$H$26 -> 85.597181 | AC32: =SUM(AA32:AB32) -> 235.91097 | AE32: 29 | AG32: {=MMULT(AG31:AI31,$G$18:$I$20)} -> 255.98797 | AH32: 208.40203 | AI32: 535.60999 | AL32: =AG32*$G$25 -> 25598.797 | AM32: =AH32*$G$26 -> 416804.07 | AN32: =SUM(AL32:AM32) -> 442402.87 | AP32: =($AG$4-AI32)*$H$35 -> 1517645.3 | AR32: =AN32+AP32 -> 1960048.2 | AT32: =AG32*$H$25 -> 217.58978 | AU32: =AH32*$H$26 -> 114.62112 | AV32: =SUM(AT32:AU32) -> 332.2109
F33: Treatment A | H33: 250 | L33: 30 | N33: {=MMULT(N32:P32,$G$5:$I$7)} -> 166.22937 | O33: 148.9101 | P33: 684.86053 | Q33: =ROUND(SUM(N33:P33),5) -> 1000 | S33: =N33*$G$25 -> 16622.937 | T33: =O33*$G$26 -> 297820.2 | U33: =SUM(S33:T33) -> 314443.14 | W33: =($N$4-P33)*$H$33 -> 78784.867 | Y33: =U33+W33 -> 393228.01 | AA33: =N33*$H$25 -> 141.29496 | AB33: =O33*$H$26 -> 81.900556 | AC33: =SUM(AA33:AB33) -> 223.19552 | AE33: 30 | AG33: {=MMULT(AG32:AI32,$G$18:$I$20)} -> 243.82854 | AH33: 203.0114 | AI33: 553.16005 | AL33: =AG33*$G$25 -> 24382.854 | AM33: =AH33*$G$26 -> 406022.8 | AN33: =SUM(AL33:AM33) -> 430405.66 | AP33: =($AG$4-AI33)*$H$35 -> 1460291 | AR33: =AN33+AP33 -> 1890696.7 | AT33: =AG33*$H$25 -> 207.25426 | AU33: =AH33*$H$26 -> 111.65627 | AV33: =SUM(AT33:AU33) -> 318.91053
L34: 31 | N34: {=MMULT(N33:P33,$G$5:$I$7)} -> 156.25561 | O34: 142.33056 | P34: 701.41383 | Q34: =ROUND(SUM(N34:P34),5) -> 1000 | S34: =N34*$G$25 -> 15625.561 | T34: =O34*$G$26 -> 284661.12 | U34: =SUM(S34:T34) -> 300286.68 | W34: =($N$4-P34)*$H$33 -> 74646.542 | Y34: =U34+W34 -> 374933.22 | AA34: =N34*$H$25 -> 132.81727 | AB34: =O34*$H$26 -> 78.281808 | AC34: =SUM(AA34:AB34) -> 211.09907 | AE34: 31 | AG34: {=MMULT(AG33:AI33,$G$18:$I$20)} -> 232.24669 | AH34: 197.53869 | AI34: 570.21462 | AL34: =AG34*$G$25 -> 23224.669 | AM34: =AH34*$G$26 -> 395077.37 | AN34: =SUM(AL34:AM34) -> 418302.04 | AP34: =($AG$4-AI34)*$H$35 -> 1404556 | AR34: =AN34+AP34 -> 1822858 | AT34: =AG34*$H$25 -> 197.40969 | AU34: =AH34*$H$26 -> 108.64628 | AV34: =SUM(AT34:AU34) -> 306.05596
F35: Treatment B | H35: 3268.0404 | L35: 32 | N35: {=MMULT(N34:P34,$G$5:$I$7)} -> 146.88027 | O35: 135.91028 | P35: 717.20945 | Q35: =ROUND(SUM(N35:P35),5) -> 1000 | S35: =N35*$G$25 -> 14688.027 | T35: =O35*$G$26 -> 271820.57 | U35: =SUM(S35:T35) -> 286508.6 | W35: =($N$4-P35)*$H$33 -> 70697.638 | Y35: =U35+W35 -> 357206.23 | AA35: =N35*$H$25 -> 124.84823 | AB35: =O35*$H$26 -> 74.750656 | AC35: =SUM(AA35:AB35) -> 199.59889 | AE35: 32 | AG35: {=MMULT(AG34:AI34,$G$18:$I$20)} -> 221.21497 | AH35: 192.01315 | AI35: 586.77188 | AL35: =AG35*$G$25 -> 22121.497 | AM35: =AH35*$G$26 -> 384026.31 | AN35: =SUM(AL35:AM35) -> 406147.8 | AP35: =($AG$4-AI35)*$H$35 -> 1350446.2 | AR35: =AN35+AP35 -> 1756594 | AT35: =AG35*$H$25 -> 188.03273 | AU35: =AH35*$H$26 -> 105.60723 | AV35: =SUM(AT35:AU35) -> 293.63996
L36: 33 | N36: {=MMULT(N35:P35,$G$5:$I$7)} -> 138.06745 | O36: 129.66327 | P36: 732.26928 | Q36: =ROUND(SUM(N36:P36),5) -> 1000 | S36: =N36*$G$25 -> 13806.745 | T36: =O36*$G$26 -> 259326.54 | U36: =SUM(S36:T36) -> 273133.28 | W36: =($N$4-P36)*$H$33 -> 66932.681 | Y36: =U36+W36 -> 340065.96 | AA36: =N36*$H$25 -> 117.35734 | AB36: =O36*$H$26 -> 71.314798 | AC36: =SUM(AA36:AB36) -> 188.67213 | AE36: 33 | AG36: {=MMULT(AG35:AI35,$G$18:$I$20)} -> 210.70726 | AH36: 186.46077 | AI36: 602.83197 | AL36: =AG36*$G$25 -> 21070.726 | AM36: =AH36*$G$26 -> 372921.53 | AN36: =SUM(AL36:AM36) -> 393992.26 | AP36: =($AG$4-AI36)*$H$35 -> 1297961.2 | AR36: =AN36+AP36 -> 1691953.4 | AT36: =AG36*$H$25 -> 179.10117 | AU36: =AH36*$H$26 -> 102.55342 | AV36: =SUM(AT36:AU36) -> 281.65459
L37: 34 | N37: {=MMULT(N36:P36,$G$5:$I$7)} -> 129.78341 | O37: 123.60032 | P37: 746.61628 | Q37: =ROUND(SUM(N37:P37),5) -> 1000 | S37: =N37*$G$25 -> 12978.341 | T37: =O37*$G$26 -> 247200.63 | U37: =SUM(S37:T37) -> 260178.97 | W37: =($N$4-P37)*$H$33 -> 63345.93 | Y37: =U37+W37 -> 323524.9 | AA37: =N37*$H$25 -> 110.3159 | AB37: =O37*$H$26 -> 67.980173 | AC37: =SUM(AA37:AB37) -> 178.29607 | AE37: 34 | AG37: {=MMULT(AG36:AI36,$G$18:$I$20)} -> 200.69866 | AH37: 180.9045 | AI37: 618.39684 | AL37: =AG37*$G$25 -> 20069.866 | AM37: =AH37*$G$26 -> 361809 | AN37: =SUM(AL37:AM37) -> 381878.86 | AP37: =($AG$4-AI37)*$H$35 -> 1247094.6 | AR37: =AN37+AP37 -> 1628973.4 | AT37: =AG37*$H$25 -> 170.59387 | AU37: =AH37*$H$26 -> 99.497474 | AV37: =SUM(AT37:AU37) -> 270.09134
F38: Results | L38: 35 | N38: {=MMULT(N37:P37,$G$5:$I$7)} -> 121.9964 | O38: 117.72945 | P38: 760.27414 | Q38: =ROUND(SUM(N38:P38),5) -> 1000 | S38: =N38*$G$25 -> 12199.64 | T38: =O38*$G$26 -> 235458.91 | U38: =SUM(S38:T38) -> 247658.55 | W38: =($N$4-P38)*$H$33 -> 59931.464 | Y38: =U38+W38 -> 307590.01 | AA38: =N38*$H$25 -> 103.69694 | AB38: =O38*$H$26 -> 64.7512 | AC38: =SUM(AA38:AB38) -> 168.44814 | AE38: 35 | AG38: {=MMULT(AG37:AI37,$G$18:$I$20)} -> 191.16548 | AH38: 175.36461 | AI38: 633.46991 | AL38: =AG38*$G$25 -> 19116.548 | AM38: =AH38*$G$26 -> 350729.22 | AN38: =SUM(AL38:AM38) -> 369845.76 | AP38: =($AG$4-AI38)*$H$35 -> 1197835.1 | AR38: =AN38+AP38 -> 1567680.9 | AT38: =AG38*$H$25 -> 162.49066 | AU38: =AH38*$H$26 -> 96.450534 | AV38: =SUM(AT38:AU38) -> 258.94119
G39: Total Costs | H39: Total QALYs | I39: NMB | L39: 36 | N39: {=MMULT(N38:P38,$G$5:$I$7)} -> 114.67662 | O39: 112.05633 | P39: 773.26705 | Q39: =ROUND(SUM(N39:P39),5) -> 1000 | S39: =N39*$G$25 -> 11467.662 | T39: =O39*$G$26 -> 224112.66 | U39: =SUM(S39:T39) -> 235580.32 | W39: =($N$4-P39)*$H$33 -> 56683.237 | Y39: =U39+W39 -> 292263.56 | AA39: =N39*$H$25 -> 97.475125 | AB39: =O39*$H$26 -> 61.630981 | AC39: =SUM(AA39:AB39) -> 159.10611 | AE39: 36 | AG39: {=MMULT(AG38:AI38,$G$18:$I$20)} -> 182.08512 | AH39: 169.85888 | AI39: 648.056 | AL39: =AG39*$G$25 -> 18208.512 | AM39: =AH39*$G$26 -> 339717.76 | AN39: =SUM(AL39:AM39) -> 357926.27 | AP39: =($AG$4-AI39)*$H$35 -> 1150167.2 | AR39: =AN39+AP39 -> 1508093.5 | AT39: =AG39*$H$25 -> 154.77235 | AU39: =AH39*$H$26 -> 93.422385 | AV39: =SUM(AT39:AU39) -> 248.19474
F40: Treatment A | G40: =Y41 -> 19535.196 | H40: =AC41 -> 16.14261 | I40: =($B$45*H40)-G40 -> 464743.1
...

Sheet help
A1: Cycle | B1: PFS (A) | C1: PFS (B) | E1: Cycle | F1: OS (A) | G1: OS (B) | J1: Treatment A | K1: Treatment B
A2: 1 | B2: =MARKOV!N4 -> 1000 | C2: =MARKOV!AG4 -> 1000 | E2: 1 | F2: =1000-MARKOV!P4 -> 1000 | G2: =1000-MARKOV!AI4 -> 1000 | I2: PFS Cost | J2: =MARKOV!S41 -> 1487.0066 | K2: =MARKOV!AL41 -> 1740.1346
A3: 2 | B3: =MARKOV!N5 -> 940 | C3: =MARKOV!AG5 -> 952.5 | E3: 2 | F3: =1000-MARKOV!P5 -> 990 | G3: =1000-MARKOV!AI5 -> 992.5 | I3: PD Cost | J3: =MARKOV!T41 -> 12738.376 | K3: =MARKOV!AM41 -> 14177.359
A4: 3 | B4: =MARKOV!N6 -> 883.6 | C4: =MARKOV!AG6 -> 907.25625 | E4: 3 | F4: =1000-MARKOV!P6 -> 975.6 | G4: =1000-MARKOV!AI6 -> 982.35625 | I4: Drug Cost | J4: =MARKOV!W41 -> 5309.8136 | K4: =MARKOV!AP41 -> 80034.393
A5: 4 | B5: =MARKOV!N7 -> 830.584 | C5: =MARKOV!AG7 -> 864.16158 | E5: 4 | F5: =1000-MARKOV!P7 -> 957.564 | G5: =1000-MARKOV!AI7 -> 969.91933
A6: 5 | B6: =MARKOV!N8 -> 780.74896 | C6: =MARKOV!AG8 -> 823.1139 | E6: 5 | F6: =1000-MARKOV!P8 -> 936.56016 | G6: =1000-MARKOV!AI8 -> 955.50629
A7: 6 | B7: =MARKOV!N9 -> 733.90402 | C7: =MARKOV!AG9 -> 784.01599 | E7: 6 | F7: =1000-MARKOV!P9 -> 913.17155 | G7: =1000-MARKOV!AI9 -> 939.4035
A8: 7 | B8: =MARKOV!N10 -> 689.86978 | C8: =MARKOV!AG10 -> 746.77523 | E8: 7 | F8: =1000-MARKOV!P10 -> 887.90576 | G8: =1000-MARKOV!AI10 -> 921.86932
A9: 8 | B9: =MARKOV!N11 -> 648.47759 | C9: =MARKOV!AG11 -> 711.30341 | E9: 8 | F9: =1000-MARKOV!P11 -> 861.20346 | G9: =1000-MARKOV!AI11 -> 903.13645
A10: 9 | B10: =MARKOV!N12 -> 609.56894 | C10: =MARKOV!AG12 -> 677.5165 | E10: 9 | F10: =1000-MARKOV!P12 -> 833.4461 | G10: =1000-MARKOV!AI12 -> 883.41419
A11: 10 | B11: =MARKOV!N13 -> 572.9948 | C11: =MARKOV!AG13 -> 645.33446 | E11: 10 | F11: =1000-MARKOV!P13 -> 804.96269 | G11: =1000-MARKOV!AI13 -> 862.89049
A12: 11 | B12: =MARKOV!N14 -> 538.61511 | C12: =MARKOV!AG14 -> 614.68108 | E12: 11 | F12: =1000-MARKOV!P14 -> 776.03596 | G12: =1000-MARKOV!AI14 -> 841.73378
A13: 12 | B13: =MARKOV!N15 -> 506.29821 | C13: =MARKOV!AG15 -> 585.48373 | E13: 12 | F13: =1000-MARKOV!P15 -> 746.90772 | G13: =1000-MARKOV!AI15 -> 820.09472
A14: 13 | B14: =MARKOV!N16 -> 475.92031 | C14: =MARKOV!AG16 -> 557.67325 | E14: 13 | F14: =1000-MARKOV!P16 -> 717.78379 | G14: =1000-MARKOV!AI16 -> 798.10777
A15: 14 | B15: =MARKOV!N17 -> 447.3651 | C15: =MARKOV!AG17 -> 531.18377 | E15: 14 | F15: =1000-MARKOV!P17 -> 688.83824 | G15: =1000-MARKOV!AI17 -> 775.89263
A16: 15 | B16: =MARKOV!N18 -> 420.52319 | C16: =MARKOV!AG18 -> 505.95254 | E16: 15 | F16: =1000-MARKOV!P18 -> 660.21727 | G16: =1000-MARKOV!AI18 -> 753.55559
... A37: 36 | B37: =MARKOV!N39 -> 114.67662 | C37: =MARKOV!AG39 -> 182.08512 | E37: 36 | F37: =1000-MARKOV!P39 -> 226.73295 | G37: =1000-MARKOV!AI39 -> 351.944
